[2023-07-22T16:31:57.576+0000] {taskinstance.py:1165} INFO - Dependencies all met for <TaskInstance: BigC_assignment.step_1_insert_data manual__2023-07-22T16:15:06.846029+00:00 [queued]>
[2023-07-22T16:31:57.592+0000] {taskinstance.py:1165} INFO - Dependencies all met for <TaskInstance: BigC_assignment.step_1_insert_data manual__2023-07-22T16:15:06.846029+00:00 [queued]>
[2023-07-22T16:31:57.593+0000] {taskinstance.py:1362} INFO - 
--------------------------------------------------------------------------------
[2023-07-22T16:31:57.594+0000] {taskinstance.py:1363} INFO - Starting attempt 1 of 4
[2023-07-22T16:31:57.595+0000] {taskinstance.py:1364} INFO - 
--------------------------------------------------------------------------------
[2023-07-22T16:31:57.621+0000] {taskinstance.py:1383} INFO - Executing <Task(PythonOperator): step_1_insert_data> on 2023-07-22 16:15:06.846029+00:00
[2023-07-22T16:31:57.633+0000] {standard_task_runner.py:54} INFO - Started process 2374 to run task
[2023-07-22T16:31:57.647+0000] {standard_task_runner.py:82} INFO - Running: ['***', 'tasks', 'run', 'BigC_assignment', 'step_1_insert_data', 'manual__2023-07-22T16:15:06.846029+00:00', '--job-id', '8', '--raw', '--subdir', 'DAGS_FOLDER/bigc_assignment_pipeline.py', '--cfg-path', '/tmp/tmp7hnt31l6']
[2023-07-22T16:31:57.651+0000] {standard_task_runner.py:83} INFO - Job 8: Subtask step_1_insert_data
[2023-07-22T16:31:57.654+0000] {dagbag.py:525} INFO - Filling up the DagBag from /opt/***/dags/bigc_assignment_pipeline.py
[2023-07-22T16:31:58.286+0000] {task_command.py:384} INFO - Running <TaskInstance: BigC_assignment.step_1_insert_data manual__2023-07-22T16:15:06.846029+00:00 [running]> on host b852f19ea805
[2023-07-22T16:31:58.392+0000] {taskinstance.py:1592} INFO - Exporting the following env vars:
AIRFLOW_CTX_DAG_OWNER=Pitchakorn_Prasertmet
AIRFLOW_CTX_DAG_ID=BigC_assignment
AIRFLOW_CTX_TASK_ID=step_1_insert_data
AIRFLOW_CTX_EXECUTION_DATE=2023-07-22T16:15:06.846029+00:00
AIRFLOW_CTX_TRY_NUMBER=1
AIRFLOW_CTX_DAG_RUN_ID=manual__2023-07-22T16:15:06.846029+00:00
[2023-07-22T16:31:58.401+0000] {taskinstance.py:1851} ERROR - Task failed with exception
Traceback (most recent call last):
  File "/home/airflow/.local/lib/python3.7/site-packages/airflow/operators/python.py", line 175, in execute
    return_value = self.execute_callable()
  File "/home/airflow/.local/lib/python3.7/site-packages/airflow/operators/python.py", line 193, in execute_callable
    return self.python_callable(*self.op_args, **self.op_kwargs)
  File "/opt/airflow/dags/step_1_insert_data.py", line 10, in insert_data
    f = pd.read_csv('raw_data.csv')
  File "/home/airflow/.local/lib/python3.7/site-packages/pandas/util/_decorators.py", line 311, in wrapper
    return func(*args, **kwargs)
  File "/home/airflow/.local/lib/python3.7/site-packages/pandas/io/parsers/readers.py", line 586, in read_csv
    return _read(filepath_or_buffer, kwds)
  File "/home/airflow/.local/lib/python3.7/site-packages/pandas/io/parsers/readers.py", line 482, in _read
    parser = TextFileReader(filepath_or_buffer, **kwds)
  File "/home/airflow/.local/lib/python3.7/site-packages/pandas/io/parsers/readers.py", line 811, in __init__
    self._engine = self._make_engine(self.engine)
  File "/home/airflow/.local/lib/python3.7/site-packages/pandas/io/parsers/readers.py", line 1040, in _make_engine
    return mapping[engine](self.f, **self.options)  # type: ignore[call-arg]
  File "/home/airflow/.local/lib/python3.7/site-packages/pandas/io/parsers/c_parser_wrapper.py", line 51, in __init__
    self._open_handles(src, kwds)
  File "/home/airflow/.local/lib/python3.7/site-packages/pandas/io/parsers/base_parser.py", line 229, in _open_handles
    errors=kwds.get("encoding_errors", "strict"),
  File "/home/airflow/.local/lib/python3.7/site-packages/pandas/io/common.py", line 707, in get_handle
    newline="",
FileNotFoundError: [Errno 2] No such file or directory: 'raw_data.csv'
[2023-07-22T16:31:58.421+0000] {taskinstance.py:1406} INFO - Marking task as UP_FOR_RETRY. dag_id=BigC_assignment, task_id=step_1_insert_data, execution_date=20230722T161506, start_date=20230722T163157, end_date=20230722T163158
[2023-07-22T16:31:58.443+0000] {standard_task_runner.py:107} ERROR - Failed to execute job 8 for task step_1_insert_data ([Errno 2] No such file or directory: 'raw_data.csv'; 2374)
[2023-07-22T16:31:58.503+0000] {local_task_job.py:164} INFO - Task exited with return code 1
[2023-07-22T16:31:58.549+0000] {local_task_job.py:273} INFO - 0 downstream tasks scheduled from follow-on schedule check
